2025-10-12 18:36:39,531 - INFO - Usando dispositivo: cuda
/home/exx/users/nicolas/venv/lib/python3.10/site-packages/torch/autograd/graph.py:829: UserWarning: Attempting to run cuBLAS, but there was no current CUDA context! Attempting to set the primary context... (Triggered internally at /pytorch/aten/src/ATen/cuda/CublasHandlePool.cpp:179.)
  return Variable._execution_engine.run_backward(  # Calls into the C++ engine to run the backward pass
2025-10-12 18:36:40,561 - INFO - Epoch 0 - Loss: 3.62e-01 - Time: 0.18s
2025-10-12 18:36:45,442 - INFO - Epoch 250 - Loss: 1.01e-01 - Time: 4.88s
2025-10-12 18:36:50,323 - INFO - Epoch 500 - Loss: 1.03e-01 - Time: 4.88s
2025-10-12 18:36:55,199 - INFO - Epoch 750 - Loss: 3.03e-01 - Time: 4.88s
2025-10-12 18:37:00,090 - INFO - Epoch 1000 - Loss: 3.03e-01 - Time: 4.89s
2025-10-12 18:37:04,999 - INFO - Epoch 1250 - Loss: 3.03e-01 - Time: 4.91s
2025-10-12 18:37:09,907 - INFO - Epoch 1500 - Loss: 3.03e-01 - Time: 4.91s
2025-10-12 18:37:14,815 - INFO - Epoch 1750 - Loss: 3.03e-01 - Time: 4.91s
2025-10-12 18:37:19,723 - INFO - Epoch 2000 - Loss: 3.03e-01 - Time: 4.91s
Traceback (most recent call last):
  File "/home/exx/users/nicolas/TCC/BurgersEquation/2_Train.py", line 151, in <module>
    plt.semilogy(loss_array[:, 2], 'g--', linewidth=1.5, label='Loss EDP')
IndexError: index 2 is out of bounds for axis 1 with size 2
